Workbook
Name Clean.Table: Clean_Table[#All]
Name Slicer_Provider_Name: #N/A
Name Slicer_Specialty1: #N/A

Sheet Raw Data
A1: Provider ID | B1: Provider Name | C1: Specialty | D1: Years Experience | E1: Monthly RVUs | F1: Monthly Visits | G1: Base Salary | H1: Bonus | I1: Total Compensation
A2: P001 | B2: Smith | C2: Orthopedics | D2: 12 | E2: 820 | F2: 310 | G2: 220000 | H2: 4500
A3: P002 | B3: Johnson | C3: Endocrinology | D3: 8 | E3: 540 | F3: 280 | G3: 180000 | H3: 2000
A4: P003 | B4: Williams | C4: Neurology | D4: 15 | E4: 910 | F4: 260 | G4: 250000 | H4: 6000
A5: P004 | B5: Brown | C5: Gastroenterology | D5: 6 | E5: 480 | F5: 300 | G5: 170000 | H5: 1500
A6: P005 | B6: Jones | C6: Orthopedics | D6: 10 | E6: 760 | F6: 295 | G6: 210000 | H6: 3500
A7: P006 | B7: Miller | C7: Endocrinology | D7: 5 | E7: 500 | F7: 270 | G7: 165000 | H7: 1200
A8: P007 | B8: Davis | C8: Cardiology | D8: 18 | E8: 1020 | F8: 240 | G8: 280000 | H8: 8000
A9: P008 | B9: Garcia | C9: Gastroenterology | D9: 7 | E9: 530 | F9: 530 | G9: 175000 | H9: 1800
A10: P009 | B10: Martinez | C10: Neurology | D10: 11 | E10: 870 | F10: 255 | G10: 240000 | H10: 5000
A11: P010 | B11: Hernandez | C11: Endocrinology | D11: 4 | E11: 460 | F11: 260 | G11: 160000 | H11: 1000
A12: P011 | B12: Lopez | C12: Orthopedics | D12: 9 | E12: 790 | F12: 300 | G12: 215000 | H12: 4000
A13: P012 | B13: Gonzalez | C13: Cardiology | D13: 14 | E13: 980 | F13: 230 | G13: 270000 | H13: 7500
... A16: P015 | B16: Thomas | C16: Endocrinology | D16: 3 | E16: 420 | F16: 240 | G16: 150000 | H16: 800

Sheet Clean Data
A1: Provider ID | B1: Provider Name | C1: Specialty | D1: Years Experience | E1: Monthly RVUs | F1: Monthly Visits | G1: Base Salary | H1: Bonus | I1: Total Compensation | J1: Comp per RVU | K1: Comp per Visit | L1: Z-scores of comp per RVU | M1: Target Comp per RVU | N1: Expected Comp | O1: Variance | P1: Bonus %
A2: P001 | B2: Smith | C2: Orthopedics | D2: 12 | E2: 820 | F2: 310 | G2: 220000 | H2: 4500 | I2: =SUM(G2+H2) -> 224500 | J2: =(I2/12)/E2 -> 22.815041 | K2: =((I2/12)/F2) -> 60.349462 | L2: =STANDARDIZE(Clean_Table[[#This Row],[Comp per RVU]], AVERAGE(Clean_Table[Comp per RVU]), _xlfn.STDEV.S(Clean_Table[Comp per RVU])) -> -1.0706625 | M2: =_xlfn.XLOOKUP(Clean_Table[[#This Row],[Specialty]], 'Pivot Tables'!$B$41:$B$46, 'Pivot Tables'!$C$41:$C$46) -> 23.108798 | N2: =(Clean_Table[[#This Row],[Monthly RVUs]]*Clean_Table[[#This Row],[Target Comp per RVU]])*12 -> 227390.57 | O2: =Clean_Table[[#This Row],[Total Compensation]]-Clean_Table[[#This Row],[Expected Comp]] -> -2890.573 | P2: =(Clean_Table[[#This Row],[Bonus]]/Clean_Table[[#This Row],[Total Compensation]])*100 -> 2.0044543
A3: P002 | B3: Johnson | C3: Endocrinology | D3: 8 | E3: 540 | F3: 280 | G3: 180000 | H3: 2000 | I3: =SUM(G3+H3) -> 182000 | J3: =(I3/12)/E3 -> 28.08642 | K3: =((I3/12)/F3) -> 54.166667 | L3: =STANDARDIZE(Clean_Table[[#This Row],[Comp per RVU]], AVERAGE(Clean_Table[Comp per RVU]), _xlfn.STDEV.S(Clean_Table[Comp per RVU])) -> 0.79382041 | M3: =_xlfn.XLOOKUP(Clean_Table[[#This Row],[Specialty]], 'Pivot Tables'!$B$41:$B$46, 'Pivot Tables'!$C$41:$C$46) -> 28.71843 | N3: =(Clean_Table[[#This Row],[Monthly RVUs]]*Clean_Table[[#This Row],[Target Comp per RVU]])*12 -> 186095.43 | O3: =Clean_Table[[#This Row],[Total Compensation]]-Clean_Table[[#This Row],[Expected Comp]] -> -4095.4286 | P3: =(Clean_Table[[#This Row],[Bonus]]/Clean_Table[[#This Row],[Total Compensation]])*100 -> 1.0989011
A4: P003 | B4: Williams | C4: Neurology | D4: 15 | E4: 910 | F4: 260 | G4: 250000 | H4: 6000 | I4: =SUM(G4+H4) -> 256000 | J4: =(I4/12)/E4 -> 23.443223 | K4: =((I4/12)/F4) -> 82.051282 | L4: =STANDARDIZE(Clean_Table[[#This Row],[Comp per RVU]], AVERAGE(Clean_Table[Comp per RVU]), _xlfn.STDEV.S(Clean_Table[Comp per RVU])) -> -0.84847475 | M4: =_xlfn.XLOOKUP(Clean_Table[[#This Row],[Specialty]], 'Pivot Tables'!$B$41:$B$46, 'Pivot Tables'!$C$41:$C$46) -> 23.455238 | N4: =(Clean_Table[[#This Row],[Monthly RVUs]]*Clean_Table[[#This Row],[Target Comp per RVU]])*12 -> 256131.19 | O4: =Clean_Table[[#This Row],[Total Compensation]]-Clean_Table[[#This Row],[Expected Comp]] -> -131.19377 | P4: =(Clean_Table[[#This Row],[Bonus]]/Clean_Table[[#This Row],[Total Compensation]])*100 -> 2.34375
A5: P004 | B5: Brown | C5: Gastroenterology | D5: 6 | E5: 480 | F5: 300 | G5: 170000 | H5: 1500 | I5: =SUM(G5+H5) -> 171500 | J5: =(I5/12)/E5 -> 29.774306 | K5: =((I5/12)/F5) -> 47.638889 | L5: =STANDARDIZE(Clean_Table[[#This Row],[Comp per RVU]], AVERAGE(Clean_Table[Comp per RVU]), _xlfn.STDEV.S(Clean_Table[Comp per RVU])) -> 1.3908244 | M5: =_xlfn.XLOOKUP(Clean_Table[[#This Row],[Specialty]], 'Pivot Tables'!$B$41:$B$46, 'Pivot Tables'!$C$41:$C$46) -> 28.646354 | N5: =(Clean_Table[[#This Row],[Monthly RVUs]]*Clean_Table[[#This Row],[Target Comp per RVU]])*12 -> 165003 | O5: =Clean_Table[[#This Row],[Total Compensation]]-Clean_Table[[#This Row],[Expected Comp]] -> 6497.0033 | P5: =(Clean_Table[[#This Row],[Bonus]]/Clean_Table[[#This Row],[Total Compensation]])*100 -> 0.87463557
A6: P005 | B6: Jones | C6: Orthopedics | D6: 10 | E6: 760 | F6: 295 | G6: 210000 | H6: 3500 | I6: =SUM(G6+H6) -> 213500 | J6: =(I6/12)/E6 -> 23.410088 | K6: =((I6/12)/F6) -> 60.310734 | L6: =STANDARDIZE(Clean_Table[[#This Row],[Comp per RVU]], AVERAGE(Clean_Table[Comp per RVU]), _xlfn.STDEV.S(Clean_Table[Comp per RVU])) -> -0.86019483 | M6: =_xlfn.XLOOKUP(Clean_Table[[#This Row],[Specialty]], 'Pivot Tables'!$B$41:$B$46, 'Pivot Tables'!$C$41:$C$46) -> 23.108798 | N6: =(Clean_Table[[#This Row],[Monthly RVUs]]*Clean_Table[[#This Row],[Target Comp per RVU]])*12 -> 210752.24 | O6: =Clean_Table[[#This Row],[Total Compensation]]-Clean_Table[[#This Row],[Expected Comp]] -> 2747.7617 | P6: =(Clean_Table[[#This Row],[Bonus]]/Clean_Table[[#This Row],[Total Compensation]])*100 -> 1.6393443
A7: P006 | B7: Miller | C7: Endocrinology | D7: 5 | E7: 500 | F7: 270 | G7: 165000 | H7: 1200 | I7: =SUM(G7+H7) -> 166200 | J7: =(I7/12)/E7 -> 27.7 | K7: =((I7/12)/F7) -> 51.296296 | L7: =STANDARDIZE(Clean_Table[[#This Row],[Comp per RVU]], AVERAGE(Clean_Table[Comp per RVU]), _xlfn.STDEV.S(Clean_Table[Comp per RVU])) -> 0.65714402 | M7: =_xlfn.XLOOKUP(Clean_Table[[#This Row],[Specialty]], 'Pivot Tables'!$B$41:$B$46, 'Pivot Tables'!$C$41:$C$46) -> 28.71843 | N7: =(Clean_Table[[#This Row],[Monthly RVUs]]*Clean_Table[[#This Row],[Target Comp per RVU]])*12 -> 172310.58 | O7: =Clean_Table[[#This Row],[Total Compensation]]-Clean_Table[[#This Row],[Expected Comp]] -> -6110.582 | P7: =(Clean_Table[[#This Row],[Bonus]]/Clean_Table[[#This Row],[Total Compensation]])*100 -> 0.72202166
A8: P007 | B8: Davis | C8: Cardiology | D8: 18 | E8: 1020 | F8: 240 | G8: 280000 | H8: 8000 | I8: =SUM(G8+H8) -> 288000 | J8: =(I8/12)/E8 -> 23.529412 | K8: =((I8/12)/F8) -> 100 | L8: =STANDARDIZE(Clean_Table[[#This Row],[Comp per RVU]], AVERAGE(Clean_Table[Comp per RVU]), _xlfn.STDEV.S(Clean_Table[Comp per RVU])) -> -0.81799 | M8: =_xlfn.XLOOKUP(Clean_Table[[#This Row],[Specialty]], 'Pivot Tables'!$B$41:$B$46, 'Pivot Tables'!$C$41:$C$46) -> 23.563175 | N8: =(Clean_Table[[#This Row],[Monthly RVUs]]*Clean_Table[[#This Row],[Target Comp per RVU]])*12 -> 288413.27 | O8: =Clean_Table[[#This Row],[Total Compensation]]-Clean_Table[[#This Row],[Expected Comp]] -> -413.26531 | P8: =(Clean_Table[[#This Row],[Bonus]]/Clean_Table[[#This Row],[Total Compensation]])*100 -> 2.7777778
A9: P008 | B9: Garcia | C9: Gastroenterology | D9: 7 | E9: 530 | F9: 530 | G9: 175000 | H9: 1800 | I9: =SUM(G9+H9) -> 176800 | J9: =(I9/12)/E9 -> 27.798742 | K9: =((I9/12)/F9) -> 27.798742 | L9: =STANDARDIZE(Clean_Table[[#This Row],[Comp per RVU]], AVERAGE(Clean_Table[Comp per RVU]), _xlfn.STDEV.S(Clean_Table[Comp per RVU])) -> 0.69206905 | M9: =_xlfn.XLOOKUP(Clean_Table[[#This Row],[Specialty]], 'Pivot Tables'!$B$41:$B$46, 'Pivot Tables'!$C$41:$C$46) -> 28.646354 | N9: =(Clean_Table[[#This Row],[Monthly RVUs]]*Clean_Table[[#This Row],[Target Comp per RVU]])*12 -> 182190.81 | O9: =Clean_Table[[#This Row],[Total Compensation]]-Clean_Table[[#This Row],[Expected Comp]] -> -5390.8088 | P9: =(Clean_Table[[#This Row],[Bonus]]/Clean_Table[[#This Row],[Total Compensation]])*100 -> 1.0180995
A10: P009 | B10: Martinez | C10: Neurology | D10: 11 | E10: 870 | F10: 255 | G10: 240000 | H10: 5000 | I10: =SUM(G10+H10) -> 245000 | J10: =(I10/12)/E10 -> 23.467433 | K10: =((I10/12)/F10) -> 80.065359 | L10: =STANDARDIZE(Clean_Table[[#This Row],[Comp per RVU]], AVERAGE(Clean_Table[Comp per RVU]), _xlfn.STDEV.S(Clean_Table[Comp per RVU])) -> -0.83991186 | M10: =_xlfn.XLOOKUP(Clean_Table[[#This Row],[Specialty]], 'Pivot Tables'!$B$41:$B$46, 'Pivot Tables'!$C$41:$C$46) -> 23.455238 | N10: =(Clean_Table[[#This Row],[Monthly RVUs]]*Clean_Table[[#This Row],[Target Comp per RVU]])*12 -> 244872.68 | O10: =Clean_Table[[#This Row],[Total Compensation]]-Clean_Table[[#This Row],[Expected Comp]] -> 127.32025 | P10: =(Clean_Table[[#This Row],[Bonus]]/Clean_Table[[#This Row],[Total Compensation]])*100 -> 2.0408163
A11: P010 | B11: Hernandez | C11: Endocrinology | D11: 4 | E11: 460 | F11: 260 | G11: 160000 | H11: 1000 | I11: =SUM(G11+H11) -> 161000 | J11: =(I11/12)/E11 -> 29.166667 | K11: =((I11/12)/F11) -> 51.602564 | L11: =STANDARDIZE(Clean_Table[[#This Row],[Comp per RVU]], AVERAGE(Clean_Table[Comp per RVU]), _xlfn.STDEV.S(Clean_Table[Comp per RVU])) -> 1.175903 | M11: =_xlfn.XLOOKUP(Clean_Table[[#This Row],[Specialty]], 'Pivot Tables'!$B$41:$B$46, 'Pivot Tables'!$C$41:$C$46) -> 28.71843 | N11: =(Clean_Table[[#This Row],[Monthly RVUs]]*Clean_Table[[#This Row],[Target Comp per RVU]])*12 -> 158525.74 | O11: =Clean_Table[[#This Row],[Total Compensation]]-Clean_Table[[#This Row],[Expected Comp]] -> 2474.2646 | P11: =(Clean_Table[[#This Row],[Bonus]]/Clean_Table[[#This Row],[Total Compensation]])*100 -> 0.62111801
A12: P011 | B12: Lopez | C12: Orthopedics | D12: 9 | E12: 790 | F12: 300 | G12: 215000 | H12: 4000 | I12: =SUM(G12+H12) -> 219000 | J12: =(I12/12)/E12 -> 23.101266 | K12: =((I12/12)/F12) -> 60.833333 | L12: =STANDARDIZE(Clean_Table[[#This Row],[Comp per RVU]], AVERAGE(Clean_Table[Comp per RVU]), _xlfn.STDEV.S(Clean_Table[Comp per RVU])) -> -0.96942491 | M12: =_xlfn.XLOOKUP(Clean_Table[[#This Row],[Specialty]], 'Pivot Tables'!$B$41:$B$46, 'Pivot Tables'!$C$41:$C$46) -> 23.108798 | N12: =(Clean_Table[[#This Row],[Monthly RVUs]]*Clean_Table[[#This Row],[Target Comp per RVU]])*12 -> 219071.41 | O12: =Clean_Table[[#This Row],[Total Compensation]]-Clean_Table[[#This Row],[Expected Comp]] -> -71.405648 | P12: =(Clean_Table[[#This Row],[Bonus]]/Clean_Table[[#This Row],[Total Compensation]])*100 -> 1.826484
A13: P012 | B13: Gonzalez | C13: Cardiology | D13: 14 | E13: 980 | F13: 230 | G13: 270000 | H13: 7500 | I13: =SUM(G13+H13) -> 277500 | J13: =(I13/12)/E13 -> 23.596939 | K13: =((I13/12)/F13) -> 100.54348 | L13: =STANDARDIZE(Clean_Table[[#This Row],[Comp per RVU]], AVERAGE(Clean_Table[Comp per RVU]), _xlfn.STDEV.S(Clean_Table[Comp per RVU])) -> -0.79410575 | M13: =_xlfn.XLOOKUP(Clean_Table[[#This Row],[Specialty]], 'Pivot Tables'!$B$41:$B$46, 'Pivot Tables'!$C$41:$C$46) -> 23.563175 | N13: =(Clean_Table[[#This Row],[Monthly RVUs]]*Clean_Table[[#This Row],[Target Comp per RVU]])*12 -> 277102.94 | O13: =Clean_Table[[#This Row],[Total Compensation]]-Clean_Table[[#This Row],[Expected Comp]] -> 397.05882 | P13: =(Clean_Table[[#This Row],[Bonus]]/Clean_Table[[#This Row],[Total Compensation]])*100 -> 2.7027027
... A16: P015 | B16: Thomas | C16: Endocrinology | D16: 3 | E16: 420 | F16: 240 | G16: 150000 | H16: 800 | I16: =SUM(G16+H16) -> 150800 | J16: =(I16/12)/E16 -> 29.920635 | K16: =((I16/12)/F16) -> 52.361111 | L16: =STANDARDIZE(Clean_Table[[#This Row],[Comp per RVU]], AVERAGE(Clean_Table[Comp per RVU]), _xlfn.STDEV.S(Clean_Table[Comp per RVU])) -> 1.442581 | M16: =_xlfn.XLOOKUP(Clean_Table[[#This Row],[Specialty]], 'Pivot Tables'!$B$41:$B$46, 'Pivot Tables'!$C$41:$C$46) -> 28.71843 | N16: =(Clean_Table[[#This Row],[Monthly RVUs]]*Clean_Table[[#This Row],[Target Comp per RVU]])*12 -> 144740.89 | O16: =Clean_Table[[#This Row],[Total Compensation]]-Clean_Table[[#This Row],[Expected Comp]] -> 6059.1111 | P16: =(Clean_Table[[#This Row],[Bonus]]/Clean_Table[[#This Row],[Total Compensation]])*100 -> 0.53050398

Sheet Pivot Tables
B9: Monthly RVUs | C9: Sum of Total Compensation | E9: Monthly RVUs | F9: Sum of Variance
B10: 420 | C10: 150800 | E10: Miller | F10: -6110.582
B11: 460 | C11: 161000 | E11: Garcia | F11: -5390.8088
B12: 500 | C12: 166200 | E12: Johnson | F12: -4095.4286
B13: 480 | C13: 171500 | E13: Smith | F13: -2890.573
B14: 510 | C14: 173600 | E14: Wilson | F14: -1715.684
B15: 530 | C15: 176800 | E15: Davis | F15: -413.26531
B16: 540 | C16: 182000 | E16: Williams | F16: -131.19377
B17: 760 | C17: 213500 | E17: Lopez | F17: -71.405648
B18: 790 | C18: 219000 | E18: Anderson | F18: -1.9367606
B19: 820 | C19: 224500 | E19: Martinez | F19: 127.32025
B20: 870 | C20: 245000 | E20: Gonzalez | F20: 397.05882
B21: 890 | C21: 250500 | E21: Hernandez | F21: 2474.2646
... B24: 1020 | C24: 288000 | E24: Brown | F24: 6497.0033
B25: Grand Total | C25: 3155900 | E25: Grand Total | F25: -2518.3581
B32: Specialty | C32: Average of Monthly RVUs | E32: Specialty & Providers | F32: Average of Comp per Visit
B33: Cardiology | C33: 1000 | E33: Cardiology | F33: 100.27174
B34: Neurology | C34: 890 | E34: Davis | F34: 100
B35: Orthopedics | C35: 790 | E35: Gonzalez | F35: 100.54348
B36: Gastroenterology | C36: 506.66667 | E36: Neurology | F36: 81.872214
B37: Endocrinology | C37: 480 | E37: Anderson | F37: 83.5
B38: Grand Total | C38: 698.66667 | E38: Martinez | F38: 80.065359
E39: Williams | F39: 82.051282
E40: Orthopedics | F40: 60.497843
B41: Specialty | C41: Average of Comp per RVU | E41: Jones | F41: 60.310734
B42: Endocrinology | C42: 28.71843 | E42: Lopez | F42: 60.833333
B43: Gastroenterology | C43: 28.646354 | E43: Smith | F43: 60.349462
B44: Cardiology | C44: 23.563175 | E44: Endocrinology | F44: 52.35666
B45: Neurology | C45: 23.455238 | E45: Hernandez | F45: 51.602564
B46: Orthopedics | C46: 23.108798 | E46: Johnson | F46: 54.166667
B47: Grand Total | C47: 25.842083 | E47: Miller | F47: 51.296296
E48: Thomas | F48: 52.361111
E49: Gastroenterology | F49: 40.956442
E50: Brown | F50: 47.638889
B51: Specialty | C51: Average of Total Compensation | E51: Garcia | F51: 27.798742
B52: Cardiology | C52: 282750 | E52: Wilson | F52: 47.431694
B53: Neurology | C53: 250500 | E53: Grand Total | F53: 63.996641
B54: Orthopedics | C54: 219000
B55: Gastroenterology | C55: 173966.67
B56: Endocrinology | C56: 165000
...

Sheet Dashboard

Sheet Questions and Answers

Sheet Summary
